<?xml version="1.0"?>
<robot xmlns:xacro="http://www.ros.org/wiki/xacro" name="robot_car">
    <xacro:include filename="robot_car_include.xacro" />
    <link name="base_link"></link>

    <joint name="chassis_joint" type="fixed">
        <parent link="base_link" />
        <child link="chassis" />
        <origin xyz="-0.2 0 0" rpy="0 0 0" />
    </joint>

    <link name="chassis">
        <visual>
            <origin xyz="0.5 0 0.2" rpy="0 0 0" />
            <geometry>
                <box size="1 1 0.4" />
            </geometry>
            <material name="blue" />
        </visual>

        <collision>
            <origin xyz="0.5 0 0.2" rpy="0 0 0" />
            <geometry>
                <box size="1 1 0.4" />
            </geometry>
        </collision>

        <xacro:inertial_box mass="2" x="1" y="1" z="0.4">
            <origin xyz="0.5 0 0.2" rpy="0 0 0" />
        </xacro:inertial_box>
    </link>

    <joint name="left_wheel_link" type="continuous">
        <parent link="base_link" />
        <child link="left_wheel" />
        <origin xyz="0 0.55 0" rpy="-${pi/2} 0 0" />
        <axis xyz="0 0 1" />
    </joint>

    <link name="left_wheel">
        <visual>
            <origin xyz="0 0 0" rpy="0 0 0" />
            <geometry>
                <cylinder radius="0.15" length="0.08" />
            </geometry>
            <material name="white" />
        </visual>

        <collision>
            <origin xyz="0 0 0" rpy="0 0 0" />
            <geometry>
                <cylinder radius="0.15" length="0.08" />
            </geometry>
        </collision>

        <xacro:inertial_cylinder mass="0.4" length="0.08" radius="0.15">
            <origin xyz="0 0 0" rpy="0 0 0" />
        </xacro:inertial_cylinder>
    </link>


    <joint name="right_wheel_link" type="continuous">
        <parent link="base_link" />
        <child link="right_wheel" />
        <origin xyz="0 -0.55 0" rpy="${pi/2} 0 0" />
        <axis xyz="0 0 1" />
    </joint>

    <link name="right_wheel">
        <visual>
            <origin xyz="0 0 0" rpy="0 0 0" />
            <geometry>
                <cylinder radius="0.15" length="0.08" />
            </geometry>
            <material name="white" />
        </visual>

        <collision>
            <origin xyz="0 0 0" rpy="0 0 0" />
            <geometry>
                <cylinder radius="0.15" length="0.08" />
            </geometry>
        </collision>

        <xacro:inertial_cylinder mass="0.2" length="0.08" radius="0.15">
            <origin xyz="0 0 0" rpy="0 0 0" />
        </xacro:inertial_cylinder>
    </link>


    <joint name="castor_joint" type="fixed">
        <parent link="chassis" />
        <child link="castor_wheel" />
        <origin xyz="0.78 0 0" rpy="0 0 0" />
    </joint>

    <link name="castor_wheel">
        <visual>
            <origin xyz="0 0 0" rpy="0 0 0" />
            <geometry>
                <sphere radius="0.15" />
            </geometry>
            <material name="green" />
        </visual>

        <collision>
            <origin xyz="0 0 0" rpy="0 0 0" />
            <geometry>
                <sphere radius="0.15" />
            </geometry>
        </collision>

        <xacro:inertial_sphere mass="0.4" radius="0.15">
            <origin xyz="0 0 0" rpy="0 0 0" />
        </xacro:inertial_sphere>
    </link>
</robot>